Workbook

Sheet Synthèse
A1: OMAR DE MOGADOR
A2: Prévisionnel financier sur 3 ans — exercices juillet 2026 → juin 2029
A3: Dossier d'ouverture de compte professionnel
A5: Statut | B5: Micro-entreprise (auto-entrepreneur) — BIC, vente de marchandises
A6: Fondateur | B6: Omar Beuthner
A7: Siège | B7: La Rochelle (17), Nouvelle-Aquitaine — omardemogador.fr
A8: Démarrage d'activité | B8: Juillet 2026
A9: Activité | B9: E-commerce de cosmétiques & bien-être orientaux premium
A10: Financement | B10: Apport personnel de 1 000 € — aucun emprunt sollicité
A12: Indicateur | B12: Année 1 (juil. 26 – juin 27) | C12: Année 2 (juil. 27 – juin 28) | D12: Année 3 (juil. 28 – juin 29)
A13: CA HT | B13: ='CR 3 ans'!B4 -> 22480 | C13: ='CR 3 ans'!C4 -> 55000 | D13: ='CR 3 ans'!D4 -> 95000
A14: Marge brute | B14: ='CR 3 ans'!B6 -> 15736 | C14: ='CR 3 ans'!C6 -> 39600 | D14: ='CR 3 ans'!D6 -> 71250
A15: Résultat net (revenu fondateur) | B15: ='CR 3 ans'!B13 -> 9036.96 | C15: ='CR 3 ans'!C13 -> 21085 | D15: ='CR 3 ans'!D13 -> 38515
A16: Marge nette | B16: ='CR 3 ans'!B14 -> 0.402 | C16: ='CR 3 ans'!C14 -> 0.38336364 | D16: ='CR 3 ans'!D14 -> 0.40542105
A17: Trésorerie de clôture | B17: =Trésorerie!I15 -> 8836.96 | C17: =Trésorerie!B28 -> 29221.96 | D17: =Trésorerie!C28 -> 66736.96
A19: Points clés
A20: • Investissement initial de 1 000 €, intégralement autofinancé — aucun emprunt, aucun découvert.
A21: • Trésorerie positive dès le premier mois d'activité ; mise de départ reconstituée au 4e mois.
A22: • Structure de coûts minimale : site, SEO et création réalisés en interne (zéro charge fixe externe).
A23: • Franchise en base de TVA jusqu'à 85 000 € ; franchissement anticipé et provisionné en année 3.
A24: • Migration en société (SASU) envisagée à partir de ~70 000 € de CA — plafond micro : 203 100 €.
A25: • Variante dropshipping (feuille dédiée) : démarrage sans stock — investissement ramené à 250 €, point bas de trésorerie porté de 161 € à 821 €.
A27: Document établi le 11 juin 2026 sur la base du business plan v1.0 (juin 2026). Détail des calculs dans les feuilles suivantes.

Sheet Hypothèses
A1: Hypothèses du modèle
A2: Source : businessplan_omar_de_mogador.pdf, v1.0, juin 2026 — paramètres modifiables (en bleu)
A4: Panier moyen (TTC = HT, franchise de TVA) | B4: 40 | C4: par commande — BP §7.1
A5: Coût d'achat des marchandises — Année 1 | B5: 0.3 | C5: marge brute 70 % — BP §7.1
A6: Coût d'achat des marchandises — Année 2 | B6: 0.28 | C6: montée en marque blanche — BP §7.4
A7: Coût d'achat des marchandises — Année 3 | B7: 0.25 | C7: BP §7.4
A8: Cotisations sociales (micro-entreprise, vente BIC) | B8: 0.123 | C8: % du CA encaissé — BP §7.1 (sans ACRE)
A9: Frais de port moyens | B9: 5.5 | C9: par commande — BP §7.1
A10: Emballage | B10: 1.5 | C10: par commande — BP §7.1
A11: CA HT cible — Année 2 | B11: 55000 | C11: scénario de base — BP §7.4
A12: CA HT cible — Année 3 | B12: 95000 | C12: scénario de base — BP §7.4
A13: Packaging & expédition — Année 2 | B13: 8250 | C13: BP §7.4
A14: Packaging & expédition — Année 3 | B14: 13300 | C14: BP §7.4
A15: Marketing & publicité — Année 2 | B15: 3000 | C15: Meta Ads dès M8 — BP §7.4
... A19: Frais de gestion — franchissement du seuil de TVA (A3) | B19: 750 | C19: comptabilité, bascule au régime réel — prudence
A21: Investissement initial (juillet 2026)
A22: Stock initial (~50 unités, 2-3 fournisseurs) | B22: 600 | C22: BP §7.2
A23: Packaging premium de lancement (100 unités) | B23: 150 | C23: BP §7.2
A24: Marketing de lancement (boosts ponctuels) | B24: 100 | C24: BP §7.2
A25: Matériel divers (emballage, imprimante à étiquettes) | B25: 150 | C25: BP §7.2
A26: Total investissement initial | B26: =SUM(B22:B25) -> 1000
A27: Apport personnel en numéraire | B27: 1000 | C27: fonds propres du fondateur
A29: Stocks
A30: Extension de stock (déc. 2026 — fêtes de fin d'année) | B30: 200 | C30: stock final A1 ≈ 800 € — BP §7.5
A31: Accroissement de stock — Année 2 | B31: 700 | C31: MOQ marque blanche
A32: Accroissement de stock — Année 3 | B32: 1000 | C32: élargissement de gamme
A34: Franchise en base de TVA jusqu'à 85 000 € de CA (seuil 2026) ; au-delà, facturation de la TVA — bascule probable en cours d'année 3.
A35: Taux de retour estimé à 2 % du CA (BP §7.1), absorbé par la prudence des hypothèses de volume.

Sheet CR mensuel A1
A1: Compte de résultat mensuel — Année 1 (juillet 2026 → juin 2027)
A2: Montée en charge conforme au business plan §7.3 — scénario de base
A3: Mois | B3: Commandes | C3: CA HT | D3: Achats marchandises | E3: Packaging & port | F3: Cotisations sociales | G3: Résultat net
A4: juil. 2026 | B4: 10 | C4: =B4*Hypothèses!$B$4 -> 400 | D4: =C4*Hypothèses!$B$5 -> 120 | E4: =B4*(Hypothèses!$B$9+Hypothèses!$B$10) -> 70 | F4: =C4*Hypothèses!$B$8 -> 49.2 | G4: =C4-D4-E4-F4 -> 160.8
A5: août 2026 | B5: 15 | C5: =B5*Hypothèses!$B$4 -> 600 | D5: =C5*Hypothèses!$B$5 -> 180 | E5: =B5*(Hypothèses!$B$9+Hypothèses!$B$10) -> 105 | F5: =C5*Hypothèses!$B$8 -> 73.8 | G5: =C5-D5-E5-F5 -> 241.2
A6: sept. 2026 | B6: 20 | C6: =B6*Hypothèses!$B$4 -> 800 | D6: =C6*Hypothèses!$B$5 -> 240 | E6: =B6*(Hypothèses!$B$9+Hypothèses!$B$10) -> 140 | F6: =C6*Hypothèses!$B$8 -> 98.4 | G6: =C6-D6-E6-F6 -> 321.6
A7: oct. 2026 | B7: 30 | C7: =B7*Hypothèses!$B$4 -> 1200 | D7: =C7*Hypothèses!$B$5 -> 360 | E7: =B7*(Hypothèses!$B$9+Hypothèses!$B$10) -> 210 | F7: =C7*Hypothèses!$B$8 -> 147.6 | G7: =C7-D7-E7-F7 -> 482.4
A8: nov. 2026 | B8: 40 | C8: =B8*Hypothèses!$B$4 -> 1600 | D8: =C8*Hypothèses!$B$5 -> 480 | E8: =B8*(Hypothèses!$B$9+Hypothèses!$B$10) -> 280 | F8: =C8*Hypothèses!$B$8 -> 196.8 | G8: =C8-D8-E8-F8 -> 643.2
A9: déc. 2026 | B9: 50 | C9: =B9*Hypothèses!$B$4 -> 2000 | D9: =C9*Hypothèses!$B$5 -> 600 | E9: =B9*(Hypothèses!$B$9+Hypothèses!$B$10) -> 350 | F9: =C9*Hypothèses!$B$8 -> 246 | G9: =C9-D9-E9-F9 -> 804
A10: janv. 2027 | B10: 55 | C10: =B10*Hypothèses!$B$4 -> 2200 | D10: =C10*Hypothèses!$B$5 -> 660 | E10: =B10*(Hypothèses!$B$9+Hypothèses!$B$10) -> 385 | F10: =C10*Hypothèses!$B$8 -> 270.6 | G10: =C10-D10-E10-F10 -> 884.4
A11: févr. 2027 | B11: 60 | C11: =B11*Hypothèses!$B$4 -> 2400 | D11: =C11*Hypothèses!$B$5 -> 720 | E11: =B11*(Hypothèses!$B$9+Hypothèses!$B$10) -> 420 | F11: =C11*Hypothèses!$B$8 -> 295.2 | G11: =C11-D11-E11-F11 -> 964.8
A12: mars 2027 | B12: 65 | C12: =B12*Hypothèses!$B$4 -> 2600 | D12: =C12*Hypothèses!$B$5 -> 780 | E12: =B12*(Hypothèses!$B$9+Hypothèses!$B$10) -> 455 | F12: =C12*Hypothèses!$B$8 -> 319.8 | G12: =C12-D12-E12-F12 -> 1045.2
A13: avr. 2027 | B13: 70 | C13: =B13*Hypothèses!$B$4 -> 2800 | D13: =C13*Hypothèses!$B$5 -> 840 | E13: =B13*(Hypothèses!$B$9+Hypothèses!$B$10) -> 490 | F13: =C13*Hypothèses!$B$8 -> 344.4 | G13: =C13-D13-E13-F13 -> 1125.6
A14: mai 2027 | B14: 72 | C14: =B14*Hypothèses!$B$4 -> 2880 | D14: =C14*Hypothèses!$B$5 -> 864 | E14: =B14*(Hypothèses!$B$9+Hypothèses!$B$10) -> 504 | F14: =C14*Hypothèses!$B$8 -> 354.24 | G14: =C14-D14-E14-F14 -> 1157.76
A15: juin 2027 | B15: 75 | C15: =B15*Hypothèses!$B$4 -> 3000 | D15: =C15*Hypothèses!$B$5 -> 900 | E15: =B15*(Hypothèses!$B$9+Hypothèses!$B$10) -> 525 | F15: =C15*Hypothèses!$B$8 -> 369 | G15: =C15-D15-E15-F15 -> 1206
A16: TOTAL ANNÉE 1 | B16: =SUM(B4:B15) -> 562 | C16: =SUM(C4:C15) -> 22480 | D16: =SUM(D4:D15) -> 6744 | E16: =SUM(E4:E15) -> 3934 | F16: =SUM(F4:F15) -> 2765.04 | G16: =SUM(G4:G15) -> 9036.96
A18: CA TTC = CA HT (franchise en base de TVA). Résultat net = revenu de l'exploitant avant impôt sur le revenu.
A19: Achats = 30 % du CA · packaging & port = 7,00 € par commande · cotisations sociales = 12,3 % du CA.

Sheet CR 3 ans
A1: Compte de résultat prévisionnel — 3 exercices
A2: Source : businessplan_omar_de_mogador.pdf, v1.0, juin 2026 §7.4
A3: Poste | B3: Année 1 (juil. 2026 – juin 2027) | C3: Année 2 (juil. 2027 – juin 2028) | D3: Année 3 (juil. 2028 – juin 2029)
A4: CA HT | B4: ='CR mensuel A1'!C16 -> 22480 | C4: =Hypothèses!B11 -> 55000 | D4: =Hypothèses!B12 -> 95000
A5: Achats de marchandises | B5: =B4*Hypothèses!$B$5 -> 6744 | C5: =C4*Hypothèses!$B$6 -> 15400 | D5: =D4*Hypothèses!$B$7 -> 23750
A6: Marge brute | B6: =B4-B5 -> 15736 | C6: =C4-C5 -> 39600 | D6: =D4-D5 -> 71250
A7: Taux de marge brute | B7: =B6/B4 -> 0.7 | C7: =C6/C4 -> 0.72 | D7: =D6/D4 -> 0.75
A8: Packaging & expédition | B8: ='CR mensuel A1'!E16 -> 3934 | C8: =Hypothèses!B13 -> 8250 | D8: =Hypothèses!B14 -> 13300
A9: Marketing & publicité | B9: 0 | C9: =Hypothèses!B15 -> 3000 | D9: =Hypothèses!B16 -> 6000
A10: Cotisations sociales (12,3 %) | B10: =B4*Hypothèses!$B$8 -> 2765.04 | C10: =C4*Hypothèses!$B$8 -> 6765 | D10: =D4*Hypothèses!$B$8 -> 11685
A11: Frais divers (abonnements, frais bancaires) | B11: 0 | C11: =Hypothèses!B17 -> 500 | D11: =Hypothèses!B18 -> 1000
A12: Frais de gestion (franchissement seuil TVA) | B12: 0 | C12: 0 | D12: =Hypothèses!B19 -> 750
A13: Résultat net (revenu du fondateur) | B13: =B6-B8-B9-B10-B11-B12 -> 9036.96 | C13: =C6-C8-C9-C10-C11-C12 -> 21085 | D13: =D6-D8-D9-D10-D11-D12 -> 38515
A14: Marge nette | B14: =B13/B4 -> 0.402 | C14: =C13/C4 -> 0.38336364 | D14: =D13/D4 -> 0.40542105
A16: Aucun amortissement (immobilisations nulles — site auto-développé) ; aucune charge financière (aucun emprunt). Résultat avant impôt sur le revenu.
A17: Année 1 : montée en charge progressive (détail mensuel en feuille « CR mensuel A1 »).

Sheet Trésorerie
A1: Plan de trésorerie — Année 1 (mensuel)
A2: Encaissements CB immédiats · cotisations réglées mensuellement · achats payés comptant (hypothèses prudentes)
A3: Mois | B3: Apport personnel | C3: CA encaissé | D3: Investissement initial | E3: Achats marchandises | F3: Packaging & port | G3: Cotisations sociales | H3: Flux du mois | I3: Trésorerie fin de mois
A4: juil. 2026 | B4: =Hypothèses!B27 -> 1000 | C4: ='CR mensuel A1'!C4 -> 400 | D4: =Hypothèses!B26 -> 1000 | E4: ='CR mensuel A1'!D4 -> 120 | F4: ='CR mensuel A1'!E4 -> 70 | G4: ='CR mensuel A1'!F4 -> 49.2 | H4: =B4+C4-D4-E4-F4-G4 -> 160.8 | I4: =H4 -> 160.8
A5: août 2026 | B5: 0 | C5: ='CR mensuel A1'!C5 -> 600 | D5: 0 | E5: ='CR mensuel A1'!D5 -> 180 | F5: ='CR mensuel A1'!E5 -> 105 | G5: ='CR mensuel A1'!F5 -> 73.8 | H5: =B5+C5-D5-E5-F5-G5 -> 241.2 | I5: =I4+H5 -> 402
A6: sept. 2026 | B6: 0 | C6: ='CR mensuel A1'!C6 -> 800 | D6: 0 | E6: ='CR mensuel A1'!D6 -> 240 | F6: ='CR mensuel A1'!E6 -> 140 | G6: ='CR mensuel A1'!F6 -> 98.4 | H6: =B6+C6-D6-E6-F6-G6 -> 321.6 | I6: =I5+H6 -> 723.6
A7: oct. 2026 | B7: 0 | C7: ='CR mensuel A1'!C7 -> 1200 | D7: 0 | E7: ='CR mensuel A1'!D7 -> 360 | F7: ='CR mensuel A1'!E7 -> 210 | G7: ='CR mensuel A1'!F7 -> 147.6 | H7: =B7+C7-D7-E7-F7-G7 -> 482.4 | I7: =I6+H7 -> 1206
A8: nov. 2026 | B8: 0 | C8: ='CR mensuel A1'!C8 -> 1600 | D8: 0 | E8: ='CR mensuel A1'!D8 -> 480 | F8: ='CR mensuel A1'!E8 -> 280 | G8: ='CR mensuel A1'!F8 -> 196.8 | H8: =B8+C8-D8-E8-F8-G8 -> 643.2 | I8: =I7+H8 -> 1849.2
A9: déc. 2026 | B9: 0 | C9: ='CR mensuel A1'!C9 -> 2000 | D9: 0 | E9: ='CR mensuel A1'!D9+Hypothèses!$B$30 -> 800 | F9: ='CR mensuel A1'!E9 -> 350 | G9: ='CR mensuel A1'!F9 -> 246 | H9: =B9+C9-D9-E9-F9-G9 -> 604 | I9: =I8+H9 -> 2453.2
A10: janv. 2027 | B10: 0 | C10: ='CR mensuel A1'!C10 -> 2200 | D10: 0 | E10: ='CR mensuel A1'!D10 -> 660 | F10: ='CR mensuel A1'!E10 -> 385 | G10: ='CR mensuel A1'!F10 -> 270.6 | H10: =B10+C10-D10-E10-F10-G10 -> 884.4 | I10: =I9+H10 -> 3337.6
A11: févr. 2027 | B11: 0 | C11: ='CR mensuel A1'!C11 -> 2400 | D11: 0 | E11: ='CR mensuel A1'!D11 -> 720 | F11: ='CR mensuel A1'!E11 -> 420 | G11: ='CR mensuel A1'!F11 -> 295.2 | H11: =B11+C11-D11-E11-F11-G11 -> 964.8 | I11: =I10+H11 -> 4302.4
A12: mars 2027 | B12: 0 | C12: ='CR mensuel A1'!C12 -> 2600 | D12: 0 | E12: ='CR mensuel A1'!D12 -> 780 | F12: ='CR mensuel A1'!E12 -> 455 | G12: ='CR mensuel A1'!F12 -> 319.8 | H12: =B12+C12-D12-E12-F12-G12 -> 1045.2 | I12: =I11+H12 -> 5347.6
A13: avr. 2027 | B13: 0 | C13: ='CR mensuel A1'!C13 -> 2800 | D13: 0 | E13: ='CR mensuel A1'!D13 -> 840 | F13: ='CR mensuel A1'!E13 -> 490 | G13: ='CR mensuel A1'!F13 -> 344.4 | H13: =B13+C13-D13-E13-F13-G13 -> 1125.6 | I13: =I12+H13 -> 6473.2
A14: mai 2027 | B14: 0 | C14: ='CR mensuel A1'!C14 -> 2880 | D14: 0 | E14: ='CR mensuel A1'!D14 -> 864 | F14: ='CR mensuel A1'!E14 -> 504 | G14: ='CR mensuel A1'!F14 -> 354.24 | H14: =B14+C14-D14-E14-F14-G14 -> 1157.76 | I14: =I13+H14 -> 7630.96
A15: juin 2027 | B15: 0 | C15: ='CR mensuel A1'!C15 -> 3000 | D15: 0 | E15: ='CR mensuel A1'!D15 -> 900 | F15: ='CR mensuel A1'!E15 -> 525 | G15: ='CR mensuel A1'!F15 -> 369 | H15: =B15+C15-D15-E15-F15-G15 -> 1206 | I15: =I14+H15 -> 8836.96
A16: TOTAL ANNÉE 1 | B16: =SUM(B4:B15) -> 1000 | C16: =SUM(C4:C15) -> 22480 | D16: =SUM(D4:D15) -> 1000 | E16: =SUM(E4:E15) -> 6944 | F16: =SUM(F4:F15) -> 3934 | G16: =SUM(G4:G15) -> 2765.04 | H16: =SUM(H4:H15) -> 8836.96 | I16: =I15 -> 8836.96
A18: Trésorerie minimale observée | B18: =MIN(I4:I15) -> 160.8 | C18: atteinte en juillet 2026 — la trésorerie reste positive chaque mois : aucun découvert ni emprunt nécessaire.
A19: Achats de décembre 2026 : réassort courant + 200 € d'extension de stock pour les fêtes (stock final ≈ 800 €).
A22: Trésorerie — Années 2 et 3 (annuel)
A23: Poste | B23: Année 2 | C23: Année 3
A24: Trésorerie d'ouverture | B24: =I15 -> 8836.96 | C24: =B28 -> 29221.96
A25: + Résultat net de l'exercice | B25: ='CR 3 ans'!C13 -> 21085 | C25: ='CR 3 ans'!D13 -> 38515
A26: − Accroissement de stock | B26: =Hypothèses!B31 -> 700 | C26: =Hypothèses!B32 -> 1000
A27: − Prélèvements de l'exploitant (non modélisés) | B27: 0 | C27: 0
A28: Trésorerie de clôture (avant prélèvements) | B28: =B24+B25-B26-B27 -> 29221.96 | C28: =C24+C25-C26-C27 -> 66736.96
A30: Le résultat net constitue la rémunération de l'exploitant en micro-entreprise ; ses prélèvements personnels restent à sa discrétion et ne sont pas modélisés ici.

Sheet Plan de financement
A1: Plan de financement initial — juillet 2026
A2: Source : businessplan_omar_de_mogador.pdf, v1.0, juin 2026 §7.2
A4: BESOINS
A5: Stock initial (~50 unités, 2-3 fournisseurs) | B5: =Hypothèses!B22 -> 600
A6: Packaging premium de lancement | B6: =Hypothèses!B23 -> 150
A7: Marketing de lancement | B7: =Hypothèses!B24 -> 100
A8: Matériel divers (emballage, imprimante à étiquettes) | B8: =Hypothèses!B25 -> 150
A9: Besoin en fonds de roulement de démarrage | B9: 0 | C9: encaissements CB immédiats, aucune créance client, stocks payés sur l'apport
A10: Total des besoins | B10: =SUM(B5:B9) -> 1000
A12: RESSOURCES
A13: Apport personnel en numéraire | B13: =Hypothèses!B27 -> 1000
A14: Emprunt bancaire | B14: 0
A15: Subventions / aides | B15: 0 | C15: aides à la création en cours d'examen — non retenues par prudence
A16: Total des ressources | B16: =SUM(B13:B15) -> 1000
A18: Équilibre (ressources − besoins) | B18: =B16-B10 -> 0
A20: Aucun financement externe n'est sollicité : l'objet du présent dossier est l'ouverture du compte professionnel.

Sheet Scénarios
A1: Scénarios de croissance
A2: Source : businessplan_omar_de_mogador.pdf, v1.0, juin 2026 §9.2
A3: Scénario | B3: CA Année 1 | C3: CA Année 2 | D3: CA Année 3 | E3: Résultat Année 1 | F3: Résultat Année 2 | G3: Résultat Année 3
A4: Conservateur | B4: 15000 | C4: 35000 | D4: 60000 | E4: =B4*('CR 3 ans'!$B$13/'CR 3 ans'!$B$4) -> 6030 | F4: =C4*('CR 3 ans'!$C$13/'CR 3 ans'!$C$4) -> 13417.727 | G4: =D4*('CR 3 ans'!$D$13/'CR 3 ans'!$D$4) -> 24325.263
A5: Base (retenu) | B5: ='CR 3 ans'!B4 -> 22480 | C5: ='CR 3 ans'!C4 -> 55000 | D5: ='CR 3 ans'!D4 -> 95000 | E5: ='CR 3 ans'!B13 -> 9036.96 | F5: ='CR 3 ans'!C13 -> 21085 | G5: ='CR 3 ans'!D13 -> 38515
A6: Optimiste | B6: 30000 | C6: 80000 | D6: 150000 | E6: =B6*('CR 3 ans'!$B$13/'CR 3 ans'!$B$4) -> 12060 | F6: =C6*('CR 3 ans'!$C$13/'CR 3 ans'!$C$4) -> 30669.091 | G6: =D6*('CR 3 ans'!$D$13/'CR 3 ans'!$D$4) -> 60813.158
A8: Conservateur : croissance lente, organique uniquement. Base : organique + marque blanche + Ads dès M8. Optimiste : viral social, B2B actif, marketplaces dès M6.
A9: Résultats des scénarios encadrants estimés par application de la marge nette du scénario de base à chaque exercice.

Sheet Variante dropshipping
A1: Variante dropshipping — démarrage sans stock
A2: Trajectoire opérationnelle décidée le 10 juin 2026 (journal de décisions) — le modèle achat-revente des feuilles précédentes reste le scénario cible ; la présente variante en sécurise le démarrage.
A4: Hypothèses spécifiques (modifiables, en bleu)
A5: Coût d'achat dropshipping (1er cercle) | B5: 0.55 | C5: marge brute 45 % — milieu de la fourchette 35–55 % (stratégie sourcing, 1er cercle)
A6: Frais de port fournisseur (expédition directe) | B6: 6 | C6: par commande — emballage et expédition assurés par le fournisseur
A7: Investissement initial réduit | B7: 250 | C7: marketing 100 € + matériel divers 150 € — ni stock (600 €) ni packaging (150 €)
A8: Part du CA en dropshipping — Année 2 | B8: 0.5 | C8: bascule progressive : références validées passées en achat-revente
A9: Part du CA en dropshipping — Année 3 | B9: 0.25 | C9: fond de gamme validé en stock, nouveautés testées en dropshipping
A10: Constitution du stock — entrée Année 2 | B10: 1300 | C10: stock initial 600 € + MOQ marque blanche 700 €, différés de l'année 1
A11: Accroissement de stock — Année 3 | B11: 1000 | C11: identique au modèle de base
A13: Trésorerie mensuelle — Année 1 (dropshipping pur)
A14: Mois | B14: Commandes | C14: CA HT | D14: Achats dropshipping | E14: Port fournisseur | F14: Cotisations sociales | G14: Flux du mois | H14: Trésorerie fin de mois
A15: juil. 2026 | B15: ='CR mensuel A1'!B4 -> 10 | C15: =B15*Hypothèses!$B$4 -> 400 | D15: =C15*$B$5 -> 220 | E15: =B15*$B$6 -> 60 | F15: =C15*Hypothèses!$B$8 -> 49.2 | G15: =Hypothèses!$B$27-$B$7+C15-D15-E15-F15 -> 820.8 | H15: =G15 -> 820.8
A16: août 2026 | B16: ='CR mensuel A1'!B5 -> 15 | C16: =B16*Hypothèses!$B$4 -> 600 | D16: =C16*$B$5 -> 330 | E16: =B16*$B$6 -> 90 | F16: =C16*Hypothèses!$B$8 -> 73.8 | G16: =C16-D16-E16-F16 -> 106.2 | H16: =H15+G16 -> 927
A17: sept. 2026 | B17: ='CR mensuel A1'!B6 -> 20 | C17: =B17*Hypothèses!$B$4 -> 800 | D17: =C17*$B$5 -> 440 | E17: =B17*$B$6 -> 120 | F17: =C17*Hypothèses!$B$8 -> 98.4 | G17: =C17-D17-E17-F17 -> 141.6 | H17: =H16+G17 -> 1068.6
A18: oct. 2026 | B18: ='CR mensuel A1'!B7 -> 30 | C18: =B18*Hypothèses!$B$4 -> 1200 | D18: =C18*$B$5 -> 660 | E18: =B18*$B$6 -> 180 | F18: =C18*Hypothèses!$B$8 -> 147.6 | G18: =C18-D18-E18-F18 -> 212.4 | H18: =H17+G18 -> 1281
A19: nov. 2026 | B19: ='CR mensuel A1'!B8 -> 40 | C19: =B19*Hypothèses!$B$4 -> 1600 | D19: =C19*$B$5 -> 880 | E19: =B19*$B$6 -> 240 | F19: =C19*Hypothèses!$B$8 -> 196.8 | G19: =C19-D19-E19-F19 -> 283.2 | H19: =H18+G19 -> 1564.2
A20: déc. 2026 | B20: ='CR mensuel A1'!B9 -> 50 | C20: =B20*Hypothèses!$B$4 -> 2000 | D20: =C20*$B$5 -> 1100 | E20: =B20*$B$6 -> 300 | F20: =C20*Hypothèses!$B$8 -> 246 | G20: =C20-D20-E20-F20 -> 354 | H20: =H19+G20 -> 1918.2
A21: janv. 2027 | B21: ='CR mensuel A1'!B10 -> 55 | C21: =B21*Hypothèses!$B$4 -> 2200 | D21: =C21*$B$5 -> 1210 | E21: =B21*$B$6 -> 330 | F21: =C21*Hypothèses!$B$8 -> 270.6 | G21: =C21-D21-E21-F21 -> 389.4 | H21: =H20+G21 -> 2307.6
A22: févr. 2027 | B22: ='CR mensuel A1'!B11 -> 60 | C22: =B22*Hypothèses!$B$4 -> 2400 | D22: =C22*$B$5 -> 1320 | E22: =B22*$B$6 -> 360 | F22: =C22*Hypothèses!$B$8 -> 295.2 | G22: =C22-D22-E22-F22 -> 424.8 | H22: =H21+G22 -> 2732.4
A23: mars 2027 | B23: ='CR mensuel A1'!B12 -> 65 | C23: =B23*Hypothèses!$B$4 -> 2600 | D23: =C23*$B$5 -> 1430 | E23: =B23*$B$6 -> 390 | F23: =C23*Hypothèses!$B$8 -> 319.8 | G23: =C23-D23-E23-F23 -> 460.2 | H23: =H22+G23 -> 3192.6
A24: avr. 2027 | B24: ='CR mensuel A1'!B13 -> 70 | C24: =B24*Hypothèses!$B$4 -> 2800 | D24: =C24*$B$5 -> 1540 | E24: =B24*$B$6 -> 420 | F24: =C24*Hypothèses!$B$8 -> 344.4 | G24: =C24-D24-E24-F24 -> 495.6 | H24: =H23+G24 -> 3688.2
A25: mai 2027 | B25: ='CR mensuel A1'!B14 -> 72 | C25: =B25*Hypothèses!$B$4 -> 2880 | D25: =C25*$B$5 -> 1584 | E25: =B25*$B$6 -> 432 | F25: =C25*Hypothèses!$B$8 -> 354.24 | G25: =C25-D25-E25-F25 -> 509.76 | H25: =H24+G25 -> 4197.96
A26: juin 2027 | B26: ='CR mensuel A1'!B15 -> 75 | C26: =B26*Hypothèses!$B$4 -> 3000 | D26: =C26*$B$5 -> 1650 | E26: =B26*$B$6 -> 450 | F26: =C26*Hypothèses!$B$8 -> 369 | G26: =C26-D26-E26-F26 -> 531 | H26: =H25+G26 -> 4728.96
A27: TOTAL ANNÉE 1 | B27: =SUM(B15:B26) -> 562 | C27: =SUM(C15:C26) -> 22480 | D27: =SUM(D15:D26) -> 12364 | E27: =SUM(E15:E26) -> 3372 | F27: =SUM(F15:F26) -> 2765.04 | G27: =SUM(G15:G26) -> 4728.96 | H27: =H26 -> 4728.96
A28: Point bas de trésorerie | B28: =MIN(H15:H26) -> 820.8 | C28: contre 161 € dans le modèle de base — l'apport de 1 000 € n'est jamais entamé de plus de 180 €
A30: Compte de résultat — 3 exercices (variante)
A31: Poste | B31: Année 1 (juil. 2026 – juin 2027) | C31: Année 2 (juil. 2027 – juin 2028) | D31: Année 3 (juil. 2028 – juin 2029)
A32: CA HT | B32: =C27 -> 22480 | C32: =Hypothèses!B11 -> 55000 | D32: =Hypothèses!B12 -> 95000
A33: Part du CA réalisée en dropshipping | B33: 1 | C33: =$B$8 -> 0.5 | D33: =$B$9 -> 0.25
A34: Achats de marchandises (mix dropshipping / stock) | B34: =B32*$B$5 -> 12364 | C34: =C32*($B$8*$B$5+(1-$B$8)*Hypothèses!$B$6) -> 22825 | D34: =D32*($B$9*$B$5+(1-$B$9)*Hypothèses!$B$7) -> 30875
A35: Marge brute | B35: =B32-B34 -> 10116 | C35: =C32-C34 -> 32175 | D35: =D32-D34 -> 64125
A36: Taux de marge brute | B36: =B35/B32 -> 0.45 | C36: =C35/C32 -> 0.585 | D36: =D35/D32 -> 0.675
A37: Packaging & expédition (port fournisseur en année 1) | B37: =E27 -> 3372 | C37: =Hypothèses!B13 -> 8250 | D37: =Hypothèses!B14 -> 13300
A38: Marketing & publicité | B38: 0 | C38: =Hypothèses!B15 -> 3000 | D38: =Hypothèses!B16 -> 6000
A39: Cotisations sociales (12,3 %) | B39: =B32*Hypothèses!$B$8 -> 2765.04 | C39: =C32*Hypothèses!$B$8 -> 6765 | D39: =D32*Hypothèses!$B$8 -> 11685
A40: Frais divers (abonnements, frais bancaires) | B40: 0 | C40: =Hypothèses!B17 -> 500 | D40: =Hypothèses!B18 -> 1000
A41: Frais de gestion (franchissement seuil TVA) | B41: 0 | C41: 0 | D41: =Hypothèses!B19 -> 750
A42: Résultat net (revenu du fondateur) | B42: =B35-B37-B38-B39-B40-B41 -> 3978.96 | C42: =C35-C37-C38-C39-C40-C41 -> 13660 | D42: =D35-D37-D38-D39-D40-D41 -> 31390
A43: Marge nette | B43: =B42/B32 -> 0.177 | C43: =C42/C32 -> 0.24836364 | D43: =D42/D32 -> 0.33042105
...
